Workbook

Sheet 🔍 Diagnóstico
B2: 🔍 DIAGNÓSTICO FINANCIERO — Tarjeta Costco Banamex
B3: Período analizado: 16-mar-2026 al 21-abr-2026 (37 días)
B6: 💸 Gastos totales (37 días) | C6: 💳 Pagos realizados (37 días) | D6: ⚠️ Saldo pendiente | E6: 🔥 CAT tarjeta
B7: $21,790 | C7: $12,675 | D7: $9,115 | E7: 81.5%
B10: 📊 DESGLOSE REAL DE GASTOS (período analizado)
B11: Categoría | C11: Gasto Real | D11: % del total | E11: Evaluación
B12: 🛒 Despensa / Súper (Costco+Soriana) | C12: 6637.7 | D12: 0.30461244 | E12: Costco principal, revisar frecuencia de visitas | G12: Despensa | H12: 6637.7
B13: ⛽ Gasolina | C13: 4241.39 | D13: 0.19464275 | E13: Alta — ¿optimizar rutas? | G13: Gasolina | H13: 4241.39
B14: 🍔 Comida rápida y restaurantes | C14: 2635.75 | D14: 0.1209579 | E14: 9 visitas en 37 días — fuga importante | G14: Comida | H14: 2635.75
B15: 🏪 OXXO / Tiendas conveniencia | C15: 1902 | D15: 0.087285183 | E15: 9 visitas — compras impulsivas frecuentes | G15: OXXO | H15: 1902
B16: 💊 Salud (farmacia+dental+médico) | C16: 1579 | D16: 0.072462305 | E16: Necesario, pero buscar seguro médico | G16: Salud | H16: 1579
B17: 📆 Costco a meses (cuota mensual) | C17: 1200.47 | D17: 0.055091085 | E17: 5 pagos restantes de $1,200 | G17: Costco | H17: 1200.47
B18: 🛍️ Compras online (Amazon+otros) | C18: 892.5 | D18: 0.040957953 | E18: Evaluar necesidad real | G18: Compras | H18: 892.5
B19: 👗 Ropa SHEIN | C19: 855.35 | D19: 0.039253092 | E19: $855 en una sola compra — evitable | G19: Ropa | H19: 855.35
B20: ☕ Caffenio (8 recargas) | C20: 850 | D20: 0.039007574 | E20: $850/mes en café — alta prioridad eliminar | G20: Caffenio | H20: 850
B21: 📱 Celular Telcel | C21: 479 | D21: 0.021981915 | E21: Fijo mensual | G21: Celular | H21: 479
B22: 🎬 Netflix | C22: 329 | D22: 0.015098226 | E22: ¿Realmente lo usas? | G22: Netflix | H22: 329
B23: 💰 GBM Forjadores | C23: 161 | D23: 0.0073884934 | E23: Esto es inversión — ¡mantenerlo! | G23: GBM | H23: 161
B24: TOTAL CARGOS | C24: 21790.64 | D24: 1
B26: 🚨 PROBLEMAS DETECTADOS
B27: 1️⃣ Gastas más de lo que ganas
B28: Con salario ~$10,000/mes, gastaste $21,790 en solo 37 días. Dependes de la tarjeta para cubrir la diferencia.
B29: 2️⃣ CAT del 81.5% — la tarjeta más cara de tu cartera
B30: Si no liquidas el saldo completo cada mes, los intereses te comen vivo. Por ley este banco cobra 58% anual ordinario.
B31: 3️⃣ 34% de tus gastos son discrecionales reducibles
B32: Comida rápida + OXXO + Caffenio + SHEIN + compras online = $7,464. Dinero que podría ser ahorro.
B33: 4️⃣ Sin colchón de emergencia
B34: Sin fondo de emergencia, cualquier imprevisto (salud, carro) va directo a la tarjeta, generando deuda cara.
B35: 5️⃣ OXXO es tu fuga más silenciosa
B36: 9 visitas, $1,902. En promedio $211 por visita. Son compras de conveniencia que en Costco costarían la mitad.

Sheet 💡 Plan de Acción
B2: 💡 PLAN DE ACCIÓN — Tu Ruta Hacia el Equilibrio Financiero
B3: Meta: Liquidar deuda tarjeta + construir fondo de emergencia + comenzar a invertir
B5: 💰 PRESUPUESTO MENSUAL OBJETIVO (Salario $10,000/mes estimado)
B6: Categoría | C6: Gasto Actual | D6: Presupuesto Meta | E6: Ahorro Mensual | H6: Categoría | I6: Actual | J6: Meta
B7: 🛒 Despensa/Súper | C7: 5400 | D7: 4500 | E7: 900 | F7: Planear lista semanal, reducir visitas Costco espontáneas | H7: 🛒 Despensa/Súpe | I7: 5400 | J7: 4500
B8: ⛽ Gasolina | C8: 3400 | D8: 2800 | E8: 600 | F8: Consolidar viajes, verificar rutas eficientes | H8: ⛽ Gasolina | I8: 3400 | J8: 2800
B9: 🍔 Comida rápida/restaurantes | C9: 2100 | D9: 600 | E9: 1500 | F9: Máx 2 salidas/semana. Cocinar en casa. | H9: 🍔 Comida rápida | I9: 2100 | J9: 600
B10: 🏪 OXXO/Conveniencia | C10: 1500 | D10: 300 | E10: 1200 | F10: SOLO emergencias. Comprar en Costco o Soriana. | H10: 🏪 OXXO/Convenie | I10: 1500 | J10: 300
B11: ☕ Caffenio | C11: 700 | D11: 0 | E11: 700 | F11: Eliminar. Café en casa = $0. Ahorro: $700/mes | H11: ☕ Caffenio | I11: 700 | J11: 0
B12: 💊 Salud | C12: 900 | D12: 900 | F12: Mantener. Considerar seguro médico familiar | H12: 💊 Salud | I12: 900 | J12: 900
B13: 📆 Costco a meses (cuota) | C13: 1200 | D13: 1200 | F13: Comprometido hasta liquidar (5 meses restantes) | H13: 📆 Costco a mese | I13: 1200 | J13: 1200
B14: 🛍️ Compras online | C14: 700 | D14: 200 | E14: 500 | F14: Solo si es necesidad real, no impulso | H14: 🛍️ Compras onli | I14: 700 | J14: 200
B15: 👗 Ropa/Personal | C15: 700 | D15: 300 | E15: 400 | F15: Presupuesto fijo trimestral, no mensual | H15: 👗 Ropa/Personal | I15: 700 | J15: 300
B16: 📱 Celular Telcel | C16: 479 | D16: 399 | E16: 80 | F16: Revisar plan, ¿hay uno más barato? | H16: 📱 Celular Telce | I16: 479 | J16: 399
B17: 🎬 Netflix | C17: 329 | D17: 329 | F17: Mantener si lo usas, cancelar si no | H17: 🎬 Netflix | I17: 329 | J17: 329
B18: 💰 GBM/Inversión | C18: 161 | D18: 500 | E18: -339 | F18: ¡AUMENTAR! Es lo único que genera riqueza | H18: 💰 GBM/Inversión | I18: 161 | J18: 500
B19: 🆘 Fondo de Emergencia | C19: 0 | D19: 500 | E19: -500 | F19: NUEVO — prioritario hasta tener $30,000 | H19: 🆘 Fondo de Emer | I19: 0 | J19: 500
B20: 💳 Pago extra deuda tarjeta | C20: 0 | D20: 500 | E20: -500 | F20: Para liquidar antes los $9,115 pendientes | H20: 💳 Pago extra de | I20: 0 | J20: 500
B21: TOTAL | C21: 17569 | D21: 13028 | E21: 4541
B23: Salario mensual estimado | D23: 10000
B24: Saldo libre con presupuesto meta | D24: -3028
B26: 🗓️ PLAN MES A MES — 6 MESES
B27: Mes | C27: Prioridad | D27: Meta concreta | E27: Resultado esperado
B28: Mayo 2026 | C28: 🔴 URGENTE | D28: 1) Para tarjeta en 0 cada corte. 2) Elimina Caffenio. 3) Máx 2 salidas a comer. | E28: Reducir gasto mensual a ~$8,500. Sin intereses tarjeta.
B29: Junio 2026 | C29: 🔴 URGENTE | D29: 1) Liquida el saldo pendiente $9,115 usando el ahorro de gastos. 2) Abre CETES Directo. | E29: Tarjeta en $0. Primera inversión en CETES $500.
B30: Julio 2026 | C30: 🟡 CONSTRUIR | D30: 1) Inicia fondo emergencia ($500/quincena). 2) Sube aportación GBM a $500/mes. | E30: Fondo emergencia: $1,000. Inversiones: $1,000.
B31: Agosto 2026 | C31: 🟡 CONSTRUIR | D31: 1) Evalúa cancelar Netflix si no lo usas. 2) Continúa fondo emergencia. | E31: Fondo emergencia: $3,000. Inversiones: $1,500.
B32: Sept 2026 | C32: 🟢 CRECER | D32: 1) Fondo emergencia meta $15,000. 2) Evalúa ETF o fondo índice para largo plazo. | E32: Fondo emergencia: $5,000. Inversiones: $2,500.
B33: Oct 2026 | C33: 🟢 CRECER | D33: 1) Costco a meses termina (último pago). 2) Esos $1,200 → ahorro/inversión. | E33: Sin deudas a meses. Inversión mensual: $1,700.

Sheet 📈 Proyección
B2: 📈 PROYECCIÓN — Liquidación de Deuda + Crecimiento de Ahorro
B4: ⚙️ PARÁMETROS (editables en azul)
B5: Saldo deuda tarjeta ($) | C5: 9115.16
B6: Pago extra mensual ($) | C6: 500
B7: CAT tarjeta anual (%) | C7: 0.5806
B8: Ahorro mensual ($) | C8: 500
B9: Inversión mensual ($) | C9: 500
B10: Rendimiento inversión (%) | C10: 0.1
B13: 📅 PROYECCIÓN MES A MES (12 meses) | I13: Mes | J13: Deuda | K13: Ahorro | L13: Inversión
B14: Mes | C14: Saldo Deuda | D14: Int.Mes | E14: Pago Deuda | F14: Saldo Ahorro | G14: Saldo Inversión | I14: Mayo 26 | J14: 9056.18 | K14: 500 | L14: 500
B15: Mayo 26 | C15: 9056.18 | D15: 441.02 | E15: 500 | F15: 500 | G15: 500 | I15: Junio 26 | J15: 8994.35 | K15: 1000 | L15: 1004.17
B16: Junio 26 | C16: 8994.35 | D16: 438.17 | E16: 500 | F16: 1000 | G16: 1004.17 | I16: Julio 26 | J16: 8929.53 | K16: 1500 | L16: 1512.53
B17: Julio 26 | C17: 8929.53 | D17: 435.18 | E17: 500 | F17: 1500 | G17: 1512.53 | I17: Agosto 26 | J17: 8861.57 | K17: 2000 | L17: 2025.14
B18: Agosto 26 | C18: 8861.57 | D18: 432.04 | E18: 500 | F18: 2000 | G18: 2025.14 | I18: Sept 26 | J18: 8790.32 | K18: 2500 | L18: 2542.02
B19: Sept 26 | C19: 8790.32 | D19: 428.75 | E19: 500 | F19: 2500 | G19: 2542.02 | I19: Oct 26 | J19: 8715.62 | K19: 3000 | L19: 3063.2
B20: Oct 26 | C20: 8715.62 | D20: 425.3 | E20: 500 | F20: 3000 | G20: 3063.2 | I20: Nov 26 | J20: 8637.32 | K20: 3500 | L20: 3588.73
B21: Nov 26 | C21: 8637.32 | D21: 421.69 | E21: 500 | F21: 3500 | G21: 3588.73 | I21: Dic 26 | J21: 8555.22 | K21: 4000 | L21: 4118.63
B22: Dic 26 | C22: 8555.22 | D22: 417.9 | E22: 500 | F22: 4000 | G22: 4118.63 | I22: Enero 27 | J22: 8469.15 | K22: 4500 | L22: 4652.95
B23: Enero 27 | C23: 8469.15 | D23: 413.93 | E23: 500 | F23: 4500 | G23: 4652.95 | I23: Feb 27 | J23: 8378.91 | K23: 5000 | L23: 5191.73
B24: Feb 27 | C24: 8378.91 | D24: 409.77 | E24: 500 | F24: 5000 | G24: 5191.73 | I24: Marzo 27 | J24: 8284.31 | K24: 5500 | L24: 5734.99
B25: Marzo 27 | C25: 8284.31 | D25: 405.4 | E25: 500 | F25: 5500 | G25: 5734.99 | I25: Abril 27 | J25: 8185.13 | K25: 6000 | L25: 6282.78
B26: Abril 27 | C26: 8185.13 | D26: 400.82 | E26: 500 | F26: 6000 | G26: 6282.78
B28: ✅ Con $500/mes extra, tu deuda actual de $9,115 queda liquidada antes de 2 años (considerando intereses del 58% anual). ¡Con $1,000/mes extra, en ~10 meses!

Sheet ⚙️ Configuración
B2: 💰 SISTEMA DE CONTROL FINANCIERO PERSONAL | H2: Servicio Básico
B3: Ingresa tu salario y presupuesto base — todo lo demás se calcula automáticamente | H3: Educación/Salud
H4: Transporte
B5: 📋 DATOS GENERALES | H5: Vivienda
B6: Salario Quincenal Neto | C6: 15500 | H6: Alimentación
B7: Salario Mensual (x2) | C7: =C6*2 -> 31000 | H7: Salud
B8: Meta de Ahorro (%) | C8: 0.1 | H8: Entretenimiento
B9: Meta de Inversión (%) | C9: 0.05 | H9: Comunicación
B10: Fondo de Emergencia (meses de gastos) | C10: 3 | H10: Ropa/Personal
H11: Deudas/Crédito
B12: 🏠 GASTOS FIJOS MENSUALES (Editables) | H12: Ahorro
B13: Categoría | C13: Presupuesto Mensual ($) | D13: Presupuesto Quincenal ($) | E13: Tipo | H13: Inversión
B14: Luz (CFE) | C14: 1000 | D14: =C14/2 -> 500 | E14: Servicio Básico | H14: Otros
B15: Internet | C15: 249 | D15: =C15/2 -> 124.5 | E15: Servicio Básico
B16: Gas | C16: 430 | D16: =C16/2 -> 215 | E16: Servicio Básico
B17: Monitor/Terapeuta hijo | C17: 4000 | D17: =C17/2 -> 2000 | E17: Educación/Salud
B18: Gasolina | C18: 2000 | D18: =C18/2 -> 1000 | E18: Transporte
B19: Renta/Hipoteca | C19: 1000 | D19: =C19/2 -> 500 | E19: Vivienda
B20: Agua | C20: 80 | D20: =C20/2 -> 40 | E20: Servicio Básico
B21: Seguro Coche | C21: 700 | D21: =C21/2 -> 350 | E21: Salud
B22: Celular | C22: 720 | D22: =C22/2 -> 360 | E22: Comunicación
B23: Streaming/Suscripciones | C23: 349 | D23: =C23/2 -> 174.5 | E23: Entretenimiento
B24: Despensa / Súper | C24: 5000 | D24: =C24/2 -> 2500 | E24: Alimentación
B25: Otros fijos | C25: 1800 | D25: =C25/2 -> 900 | E25: Otros
B26: TOTAL GASTOS FIJOS | C26: =SUM(C14:C25) -> 17328 | D26: =SUM(D14:D25) -> 8664
B29: 📊 RESUMEN FINANCIERO RÁPIDO
B30: Salario Mensual | C30: =C7 -> 31000
B31: (-) Total Gastos Fijos | C31: =-C26 -> -17328
B32: (-) Meta Ahorro | C32: =-C7*C8 -> -3100
B33: (-) Meta Inversión | C33: =-C7*C9 -> -1550
B34: Dinero Libre (Variable) | C34: =C7-C26-C7*C8-C7*C9 -> 9022
B35: Fondo Emergencia Meta ($) | C35: =C26*C10 -> 51984
B37: ℹ️ Azul = Celda de entrada (editable) | Negro = Fórmula automática | Verde = Resultado clave

Sheet 📝 Transacciones
B2: 📝 REGISTRO DE TRANSACCIONES — Importación de Estado de Cuenta
B3: Pega tus movimientos bancarios aquí | Formato: Fecha · Descripción · Cargo/Abono · Categoría | Puedes copiar y pegar directamente desde tu estado de cuenta PDF/CSV
B5: 💡 CÓMO IMPORTAR: (1) Descarga tu estado de cuenta en CSV/Excel desde la app del banco (2) Copia las columnas Fecha, Descripción, Cargo, Abono (3) Pégalas aquí desde la fila 8 (4) Asigna la categoría en columna F → ¡Los dashboards se actualizan solos!
B7: # | C7: Fecha | D7: Descripción / Concepto | E7: Cargo ($) | F7: Abono ($) | G7: Categoría | H7: Subcuenta | I7: Quincena | J7: Notas / Referencia
B8: 1 | C8: 16/03/2026 | D8: COSTCO LOS CABOS | E8: 5 | G8: Alimentación | H8: Súper/Despensa | I8: 1ra Quincena Mar
B9: 2 | C9: 19/03/2026 | D9: LITTLE CAESARS | E9: 189 | G9: Alimentación | H9: Restaurantes | I9: 1ra Quincena Mar
B10: 3 | C10: 21/03/2026 | D10: OXXOSAN BERNABE CEN | E10: 194 | G10: OXXO/Conveniencia | H10: OXXO | I10: 1ra Quincena Mar
B11: 4 | C11: 22/03/2026 | D11: OPENPAY*CAFFENIO RECARGA | E11: 100 | G11: Entretenimiento | H11: Caffenio | I11: 2da Quincena Mar | J11: ⚠️ Fuga
B12: 5 | C12: 23/03/2026 | D12: OXXOSAN BERNABE CEN | E12: 98 | G12: OXXO/Conveniencia | H12: OXXO | I12: 1ra Quincena Mar
B13: 6 | C13: 23/03/2026 | D13: FARMACIAS SIMILARES | E13: 339 | G13: Salud | H13: Farmacia | I13: 1ra Quincena Mar
B14: 7 | C14: 23/03/2026 | D14: COSTCO LOS CABOS | E14: 792.6 | G14: Alimentación | H14: Súper/Despensa | I14: 1ra Quincena Mar
B15: 8 | C15: 23/03/2026 | D15: COSTCO LOS CABOS | E15: 449 | G15: Alimentación | H15: Súper/Despensa | I15: 1ra Quincena Mar
B16: 9 | C16: 23/03/2026 | D16: OPENPAY*CAFFENIO RECARGA | E16: 100 | G16: Entretenimiento | H16: Caffenio | I16: 2da Quincena Mar | J16: ⚠️ Fuga
B17: 10 | C17: 24/03/2026 | D17: ESTACION 2864 DISTRIBU | E17: 966.13 | G17: Transporte | H17: Gasolina | I17: 1ra Quincena Mar
B18: 11 | C18: 27/03/2026 | D18: TELCEL 1MPS ECOM | E18: 479 | G18: Comunicación | H18: Celular | I18: 2da Quincena Mar
B19: 12 | C19: 28/03/2026 | D19: SORIANA LOS CABOS | E19: 783 | G19: Alimentación | H19: Súper/Despensa | I19: 2da Quincena Mar
B20: 13 | C20: 28/03/2026 | D20: OXXO CHAMIZAL LAP | E20: 623 | G20: OXXO/Conveniencia | H20: OXXO | I20: 2da Quincena Mar
B21: 14 | C21: 28/03/2026 | D21: SU ABONO...GRACIAS | F21: 449 | G21: Abono | H21: Pago tarjeta | I21: 2da Quincena Mar
B22: 15 | C22: 30/03/2026 | D22: AMAZON | E22: 271.53 | G22: Compras Online | H22: Amazon | I22: 2da Quincena Mar
B23: 16 | C23: 31/03/2026 | D23: CARLS JR SAN LUCAS | E23: 799 | G23: Alimentación | H23: Restaurantes | I23: 2da Quincena Mar
B24: 17 | C24: 31/03/2026 | D24: RAPPI VERIFICACION | E24: 27.48 | G24: Alimentación | H24: Delivery Rappi | I24: 2da Quincena Mar
B25: 18 | C25: 31/03/2026 | D25: D LOCAL*REST RAPPI | E25: 179 | G25: Alimentación | H25: Delivery Rappi | I25: 2da Quincena Mar
B26: 19 | C26: 01/04/2026 | D26: COSTCO LOS CABOS | E26: 588 | G26: Alimentación | H26: Súper/Despensa | I26: 1ra Quincena Abr
B27: 20 | C27: 01/04/2026 | D27: OXXO PEDROZA CEN | E27: 143 | G27: OXXO/Conveniencia | H27: OXXO | I27: 1ra Quincena Abr
B28: 21 | C28: 01/04/2026 | D28: SU ABONO...GRACIAS | F28: 4600 | G28: Abono | H28: Pago tarjeta | I28: 1ra Quincena Abr
B29: 22 | C29: 01/04/2026 | D29: RAPPI VERIFICACION | F29: 27.48 | G29: Abono | H29: Devolución | I29: 1ra Quincena Abr | J29: Devolución Rappi
B30: 23 | C30: 02/04/2026 | D30: OXXOSAN BERNABE CEN | E30: 98 | G30: OXXO/Conveniencia | H30: OXXO | I30: 1ra Quincena Abr
B31: 24 | C31: 03/04/2026 | D31: OXXOSAN BERNABE CEN | E31: 332.5 | G31: OXXO/Conveniencia | H31: OXXO | I31: 1ra Quincena Abr
B32: 25 | C32: 04/04/2026 | D32: COSTCO LOS CABOS | E32: 129 | G32: Alimentación | H32: Súper/Despensa | I32: 1ra Quincena Abr
B33: 26 | C33: 04/04/2026 | D33: OPENPAY*CAFFENIO RECARGA | E33: 100 | G33: Entretenimiento | H33: Caffenio | I33: 1ra Quincena Abr | J33: ⚠️ Fuga
B34: 27 | C34: 05/04/2026 | D34: OXXOSAN BERNABE CEN | E34: 217.5 | G34: OXXO/Conveniencia | H34: OXXO | I34: 1ra Quincena Abr
B35: 28 | C35: 06/04/2026 | D35: MERPAGO*DENTAL | E35: 900 | G35: Salud | H35: Dental | I35: 1ra Quincena Abr
B36: 29 | C36: 06/04/2026 | D36: BURGER KING | E36: 411 | G36: Alimentación | H36: Restaurantes | I36: 1ra Quincena Abr
B37: 30 | C37: 06/04/2026 | D37: GASO AEROPUERTO | E37: 200 | G37: Transporte | H37: Gasolina | I37: 1ra Quincena Abr
B38: 31 | C38: 06/04/2026 | D38: COSTCO LOS CABOS | F38: 129 | G38: Abono | H38: Devolución | I38: 1ra Quincena Abr | J38: Devolución Costco
B39: 32 | C39: 06/04/2026 | D39: COSTCO GAS LOS CABOS | E39: 776.51 | G39: Transporte | H39: Gasolina | I39: 1ra Quincena Abr
B40: 33 | C40: 06/04/2026 | D40: COSTCO LOS CABOS | E40: 633.2 | G40: Alimentación | H40: Súper/Despensa | I40: 1ra Quincena Abr
B41: 34 | C41: 06/04/2026 | D41: AMAZON | E41: 144.97 | G41: Compras Online | H41: Amazon | I41: 1ra Quincena Abr
B42: 35 | C42: 06/04/2026 | D42: OPENPAY*CAFFENIO RECARGA | E42: 100 | G42: Entretenimiento | H42: Caffenio | I42: 1ra Quincena Abr | J42: ⚠️ Fuga
B43: 36 | C43: 07/04/2026 | D43: GB 3 FORJADORES | E43: 161 | G43: Inversión | H43: GBM Forjadores | I43: 1ra Quincena Abr | J43: 💰 Inversión
...

Sheet 📊 Dashboard
B2: 📊 DASHBOARD FINANCIERO MENSUAL | Q2: Categoría | R2: Gasto
Q3: Servicio Básico | R3: =SUMIF('📝 Transacciones'!G8:G228,Q3,'📝 Transacciones'!E8:E228) -> 1900
Q4: Educación/Salud | R4: =SUMIF('📝 Transacciones'!G8:G228,Q4,'📝 Transacciones'!E8:E228) -> 0
B5: 💵 INGRESO MENSUAL | E5: 🛒 TOTAL GASTOS | H5: 💰 BALANCE NETO | K5: 🎯 % AHORRO REAL | Q5: Transporte | R5: =SUMIF('📝 Transacciones'!G8:G228,Q5,'📝 Transacciones'!E8:E228) -> 7956.58
B6: ='📝 Transacciones'!F28 -> 4600 | E6: ='📝 Transacciones'!E28 -> 0 | H6: ='📝 Transacciones'!F28-'📝 Transacciones'!E28 -> 4600 | K6: =IF('📝 Transacciones'!F28>0,('📝 Transacciones'!F28-'📝 Transacciones'!E28)/'📝 Transacciones'!F28,0) -> 1 | Q6: Vivienda | R6: =SUMIF('📝 Transacciones'!G8:G228,Q6,'📝 Transacciones'!E8:E228) -> 0
Q7: Alimentación | R7: =SUMIF('📝 Transacciones'!G8:G228,Q7,'📝 Transacciones'!E8:E228) -> 24996.06
Q8: Salud | R8: =SUMIF('📝 Transacciones'!G8:G228,Q8,'📝 Transacciones'!E8:E228) -> 2649.2
Q9: Entretenimiento | R9: =SUMIF('📝 Transacciones'!G8:G228,Q9,'📝 Transacciones'!E8:E228) -> 2408
B10: 💸 GASTOS POR CATEGORÍA | Q10: Comunicación | R10: =SUMIF('📝 Transacciones'!G8:G228,Q10,'📝 Transacciones'!E8:E228) -> 758
B11: Categoría | C11: Gasto Real ($) | D11: Presupuesto ($) | E11: Diferencia ($) | F11: Estado | Q11: Ropa/Personal | R11: =SUMIF('📝 Transacciones'!G8:G228,Q11,'📝 Transacciones'!E8:E228) -> 943.24
B12: Servicio Básico | C12: =SUMIF('📝 Transacciones'!G8:G228,B12,'📝 Transacciones'!E8:E228) -> 1900 | D12: =SUM('⚙️ Configuración'!C14:C14)+'⚙️ Configuración'!C15+'⚙️ Configuración'!C16+'⚙️ Configuración'!C20 -> 1759 | E12: =D12-C12 -> -141 | F12: =IF(D12=0,"➖",IF(C12<=D12,"✅ OK","⚠️ Excedido")) -> ⚠️ Excedido | Q12: Deudas/Crédito | R12: =SUMIF('📝 Transacciones'!G8:G228,Q12,'📝 Transacciones'!E8:E228) -> 2986.28
B13: Educación/Salud | C13: =SUMIF('📝 Transacciones'!G8:G228,B13,'📝 Transacciones'!E8:E228) -> 0 | D13: ='⚙️ Configuración'!C17 -> 4000 | E13: =D13-C13 -> 4000 | F13: =IF(D13=0,"➖",IF(C13<=D13,"✅ OK","⚠️ Excedido")) -> ✅ OK | Q13: Ahorro | R13: =SUMIF('📝 Transacciones'!G8:G228,Q13,'📝 Transacciones'!E8:E228) -> 0
B14: Transporte | C14: =SUMIF('📝 Transacciones'!G8:G228,B14,'📝 Transacciones'!E8:E228) -> 7956.58 | D14: ='⚙️ Configuración'!C18 -> 2000 | E14: =D14-C14 -> -5956.58 | F14: =IF(D14=0,"➖",IF(C14<=D14,"✅ OK","⚠️ Excedido")) -> ⚠️ Excedido | Q14: Inversión | R14: =SUMIF('📝 Transacciones'!G8:G228,Q14,'📝 Transacciones'!E8:E228) -> 161
B15: Vivienda | C15: =SUMIF('📝 Transacciones'!G8:G228,B15,'📝 Transacciones'!E8:E228) -> 0 | D15: ='⚙️ Configuración'!C19 -> 1000 | E15: =D15-C15 -> 1000 | F15: =IF(D15=0,"➖",IF(C15<=D15,"✅ OK","⚠️ Excedido")) -> ✅ OK | Q15: Otros | R15: =SUMIF('📝 Transacciones'!G8:G228,Q15,'📝 Transacciones'!E8:E228) -> 19.99
B16: Alimentación | C16: =SUMIF('📝 Transacciones'!G8:G228,B16,'📝 Transacciones'!E8:E228) -> 24996.06 | D16: ='⚙️ Configuración'!C24 -> 5000 | E16: =D16-C16 -> -19996.06 | F16: =IF(D16=0,"➖",IF(C16<=D16,"✅ OK","⚠️ Excedido")) -> ⚠️ Excedido
B17: Salud | C17: =SUMIF('📝 Transacciones'!G8:G228,B17,'📝 Transacciones'!E8:E228) -> 2649.2 | D17: ='⚙️ Configuración'!C21 -> 700 | E17: =D17-C17 -> -1949.2 | F17: =IF(D17=0,"➖",IF(C17<=D17,"✅ OK","⚠️ Excedido")) -> ⚠️ Excedido
B18: Entretenimiento | C18: =SUMIF('📝 Transacciones'!G8:G228,B18,'📝 Transacciones'!E8:E228) -> 2408 | D18: ='⚙️ Configuración'!C23 -> 349 | E18: =D18-C18 -> -2059 | F18: =IF(D18=0,"➖",IF(C18<=D18,"✅ OK","⚠️ Excedido")) -> ⚠️ Excedido
B19: Comunicación | C19: =SUMIF('📝 Transacciones'!G8:G228,B19,'📝 Transacciones'!E8:E228) -> 758 | D19: ='⚙️ Configuración'!C22 -> 720 | E19: =D19-C19 -> -38 | F19: =IF(D19=0,"➖",IF(C19<=D19,"✅ OK","⚠️ Excedido")) -> ⚠️ Excedido
B20: Ropa/Personal | C20: =SUMIF('📝 Transacciones'!G8:G228,B20,'📝 Transacciones'!E8:E228) -> 943.24 | D20: 0 | E20: =D20-C20 -> -943.24 | F20: =IF(D20=0,"➖",IF(C20<=D20,"✅ OK","⚠️ Excedido")) -> ➖
B21: Deudas/Crédito | C21: =SUMIF('📝 Transacciones'!G8:G228,B21,'📝 Transacciones'!E8:E228) -> 2986.28 | D21: 0 | E21: =D21-C21 -> -2986.28 | F21: =IF(D21=0,"➖",IF(C21<=D21,"✅ OK","⚠️ Excedido")) -> ➖
B22: Ahorro | C22: =SUMIF('📝 Transacciones'!G8:G228,B22,'📝 Transacciones'!E8:E228) -> 0 | D22: ='⚙️ Configuración'!C7*'⚙️ Configuración'!C8 -> 3100 | E22: =D22-C22 -> 3100 | F22: =IF(D22=0,"➖",IF(C22<=D22,"✅ OK","⚠️ Excedido")) -> ✅ OK
B23: Inversión | C23: =SUMIF('📝 Transacciones'!G8:G228,B23,'📝 Transacciones'!E8:E228) -> 161 | D23: ='⚙️ Configuración'!C7*'⚙️ Configuración'!C9 -> 1550 | E23: =D23-C23 -> 1389 | F23: =IF(D23=0,"➖",IF(C23<=D23,"✅ OK","⚠️ Excedido")) -> ✅ OK
B24: Otros | C24: =SUMIF('📝 Transacciones'!G8:G228,B24,'📝 Transacciones'!E8:E228) -> 19.99 | D24: ='⚙️ Configuración'!C25 -> 1800 | E24: =D24-C24 -> 1780.01 | F24: =IF(D24=0,"➖",IF(C24<=D24,"✅ OK","⚠️ Excedido")) -> ✅ OK
B25: TOTAL | C25: =SUM(C12:C24) -> 44778.35 | D25: =SUM(D12:D24) -> 21978 | E25: =D25-C25 -> -22800.35

Sheet 🏦 Plan Ahorro
B2: 🏦 PLAN DE AHORRO E INVERSIÓN — Interés Compuesto
B4: ⚙️ PARÁMETROS DEL PLAN
B5: Ahorro mensual (de Config.) | C5: ='⚙️ Configuración'!C7*'⚙️ Configuración'!C8 -> 3100
B6: Inversión mensual (de Config.) | C6: ='⚙️ Configuración'!C7*'⚙️ Configuración'!C9 -> 1550
B7: Rendimiento anual estimado (%) | C7: 0.1
B8: Años de proyección | C8: 10
B9: Fondo de emergencia meta ($) | C9: ='⚙️ Configuración'!C7*2*'⚙️ Configuración'!C10 -> 186000
B11: 📈 PROYECCIÓN INTERÉS COMPUESTO (12 MESES)
B12: Mes | C12: Aportación Ahorro | D12: Aportación Inversión | E12: Total Aportado | F12: Intereses Generados | G12: Saldo Ahorro | H12: Saldo Inversión | I12: Saldo Total
B13: 1 | C13: =$C$5 -> 3100 | D13: =$C$6 -> 1550 | E13: =(C$5+C$6)*B13 -> 4650 | F13: =$C$5*(POWER(1+$C$7,1/12)-1)+$C$6*(POWER(1+$C$7,1/12)-1) -> 37.079753 | G13: =$C$5*(1+(1+$C$7)^(1/12)-1) -> 3124.7198 | H13: =$C$6*(1+(1+$C$7)^(1/12)-1) -> 1562.3599 | I13: =G13+H13 -> 4687.0798
B14: 2 | C14: =$C$5 -> 3100 | D14: =$C$6 -> 1550 | E14: =(C$5+C$6)*B14 -> 9300 | F14: =(G13+H13+$C$5+$C$6)*(POWER(1+$C$7,1/12)-1) -> 74.455185 | G14: =(G13+$C$5)*(1+(1+$C$7)^(1/12)-1)+G13+$C$5 -> 12499.076 | H14: =(H13+$C$6)*(1+(1+$C$7)^(1/12)-1)+H13+$C$6 -> 6249.5382 | I14: =G14+H14 -> 18748.615
B15: 3 | C15: =$C$5 -> 3100 | D15: =$C$6 -> 1550 | E15: =(C$5+C$6)*B15 -> 13950 | F15: =(G14+H14+$C$5+$C$6)*(POWER(1+$C$7,1/12)-1) -> 186.58384 | G15: =(G14+$C$5)*(1+(1+$C$7)^(1/12)-1)+G14+$C$5 -> 31322.542 | H15: =(H14+$C$6)*(1+(1+$C$7)^(1/12)-1)+H14+$C$6 -> 15661.271 | I15: =G15+H15 -> 46983.813
B16: 4 | C16: =$C$5 -> 3100 | D16: =$C$6 -> 1550 | E16: =(C$5+C$6)*B16 -> 18600 | F16: =(G15+H15+$C$5+$C$6)*(POWER(1+$C$7,1/12)-1) -> 411.73528 | G16: =(G15+$C$5)*(1+(1+$C$7)^(1/12)-1)+G15+$C$5 -> 69119.574 | H16: =(H15+$C$6)*(1+(1+$C$7)^(1/12)-1)+H15+$C$6 -> 34559.787 | I16: =G16+H16 -> 103679.36
B17: 5 | C17: =$C$5 -> 3100 | D17: =$C$6 -> 1550 | E17: =(C$5+C$6)*B17 -> 23250 | F17: =(G16+H16+$C$5+$C$6)*(POWER(1+$C$7,1/12)-1) -> 863.83354 | G17: =(G16+$C$5)*(1+(1+$C$7)^(1/12)-1)+G16+$C$5 -> 145015.04 | H17: =(H16+$C$6)*(1+(1+$C$7)^(1/12)-1)+H16+$C$6 -> 72507.519 | I17: =G17+H17 -> 217522.56
B18: 6 | C18: =$C$5 -> 3100 | D18: =$C$6 -> 1550 | E18: =(C$5+C$6)*B18 -> 27900 | F18: =(G17+H17+$C$5+$C$6)*(POWER(1+$C$7,1/12)-1) -> 1771.6352 | G18: =(G17+$C$5)*(1+(1+$C$7)^(1/12)-1)+G17+$C$5 -> 297411.17 | H18: =(H17+$C$6)*(1+(1+$C$7)^(1/12)-1)+H17+$C$6 -> 148705.58 | I18: =G18+H18 -> 446116.75
B19: 7 | C19: =$C$5 -> 3100 | D19: =$C$6 -> 1550 | E19: =(C$5+C$6)*B19 -> 32550 | F19: =(G18+H18+$C$5+$C$6)*(POWER(1+$C$7,1/12)-1) -> 3594.4774 | G19: =(G18+$C$5)*(1+(1+$C$7)^(1/12)-1)+G18+$C$5 -> 603418.65 | H19: =(H18+$C$6)*(1+(1+$C$7)^(1/12)-1)+H18+$C$6 -> 301709.33 | I19: =G19+H19 -> 905127.98
B20: 8 | C20: =$C$5 -> 3100 | D20: =$C$6 -> 1550 | E20: =(C$5+C$6)*B20 -> 37200 | F20: =(G19+H19+$C$5+$C$6)*(POWER(1+$C$7,1/12)-1) -> 7254.6973 | G20: =(G19+$C$5)*(1+(1+$C$7)^(1/12)-1)+G19+$C$5 -> 1217873.8 | H20: =(H19+$C$6)*(1+(1+$C$7)^(1/12)-1)+H19+$C$6 -> 608936.88 | I20: =G20+H20 -> 1826810.6
B21: 9 | C21: =$C$5 -> 3100 | D21: =$C$6 -> 1550 | E21: =(C$5+C$6)*B21 -> 41850 | F21: =(G20+H20+$C$5+$C$6)*(POWER(1+$C$7,1/12)-1) -> 14604.324 | G21: =(G20+$C$5)*(1+(1+$C$7)^(1/12)-1)+G20+$C$5 -> 2451683.7 | H21: =(H20+$C$6)*(1+(1+$C$7)^(1/12)-1)+H20+$C$6 -> 1225841.9 | I21: =G21+H21 -> 3677525.6
B22: 10 | C22: =$C$5 -> 3100 | D22: =$C$6 -> 1550 | E22: =(C$5+C$6)*B22 -> 46500 | F22: =(G21+H21+$C$5+$C$6)*(POWER(1+$C$7,1/12)-1) -> 29362.185 | G22: =(G21+$C$5)*(1+(1+$C$7)^(1/12)-1)+G21+$C$5 -> 4929142.3 | H22: =(H21+$C$6)*(1+(1+$C$7)^(1/12)-1)+H21+$C$6 -> 2464571.1 | I22: =G22+H22 -> 7393713.4
B23: 11 | C23: =$C$5 -> 3100 | D23: =$C$6 -> 1550 | E23: =(C$5+C$6)*B23 -> 51150 | F23: =(G22+H22+$C$5+$C$6)*(POWER(1+$C$7,1/12)-1) -> 58995.589 | G23: =(G22+$C$5)*(1+(1+$C$7)^(1/12)-1)+G22+$C$5 -> 9903815 | H23: =(H22+$C$6)*(1+(1+$C$7)^(1/12)-1)+H22+$C$6 -> 4951907.5 | I23: =G23+H23 -> 14855722
B24: 12 | C24: =$C$5 -> 3100 | D24: =$C$6 -> 1550 | E24: =(C$5+C$6)*B24 -> 55800 | F24: =(G23+H23+$C$5+$C$6)*(POWER(1+$C$7,1/12)-1) -> 118498.7 | G24: =(G23+$C$5)*(1+(1+$C$7)^(1/12)-1)+G23+$C$5 -> 19892829 | H24: =(H23+$C$6)*(1+(1+$C$7)^(1/12)-1)+H23+$C$6 -> 9946414.5 | I24: =G24+H24 -> 29839244
B44: 🆘 PROGRESO FONDO DE EMERGENCIA
B45: Meta fondo emergencia | C45: ='⚙️ Configuración'!C7*2*'⚙️ Configuración'!C10 -> 186000
B46: Ahorrado actualmente | C46: 0
B47: % Alcanzado | C47: =IF(C46>0,C46/C45,0) -> 0
B48: Meses restantes | C48: =IF(C5>0,MAX(0,(C45-C46)/C5),0) -> 60

Sheet 📖 Guía de Uso
B2: 📖 GUÍA DE USO RÁPIDA
B5: PASO 1 | C5: ⚙️ Configuración
B6: • Ingresa tu salario quincenal neto en celda C6
B7: • Ajusta las metas de ahorro (%) e inversión (%)
B8: • Revisa y modifica los gastos fijos según tu realidad
B9: • El resumen financiero se calcula automáticamente
B11: PASO 2 | C11: 📝 Transacciones
B12: • Agrega cada movimiento manualmente O importa desde tu banco:
B13: → App BBVA/Banamex/Santander → Estado de cuenta → Descargar CSV
B14: → Abre el CSV en Excel → Copia Fecha, Descripción, Cargos, Abonos
B15: → Pega a partir de la fila 8 en esta hoja
B16: • Asigna la categoría en columna F (menú desplegable)
B17: • Marca si es 1ra o 2da quincena en columna H
B19: PASO 3 | C19: 📊 Dashboard
B20: • Ve al Dashboard para ver tus gráficas actualizadas
B21: • Revisa los semáforos ✅/⚠️ por categoría
B22: • Identifica las categorías donde más te excedes
B23: • El % de ahorro real te dice si vas bien o mal
B25: PASO 4 | C25: 🏦 Plan Ahorro
B26: • Configura el rendimiento anual estimado (CETES ~10%, Fondo índice ~12%)
B27: • Mira cómo crece tu dinero con interés compuesto
B28: • Define cuánto necesitas para tu fondo de emergencia
B29: • Actualiza 'Ahorrado actualmente' para ver tu progreso
B31: CONSEJO | C31: 🔍 Detectar fugas
B32: • Filtra por categoría 'Otros' y 'Entretenimiento' → ahí están las fugas
B33: • Cualquier gasto marcado como 'Revisar si necesario' en Notas → evalúalo
B34: • Compara mes a mes: ¿qué categoría creció más?
B35: • Regla 50/30/20: 50% necesidades, 30% deseos, 20% ahorro

Sheet 📥 Banamex Importado
B2: 📥 IMPORTACIÓN BANAMEX — Costco Tarjeta de Crédito
B3: Período: 16-mar-2026 al 21-abr-2026 | Titular: RAUL ASTUDILLO B | Tarjeta: 4037 **** **** 7204
B5: Total Cargos: $21,790.64 | D5: Total Abonos/Pagos: $12,675.48 | F5: Movimientos: 62 | H5: Balance neto: $-9,115.16
B7: # | C7: Fecha Op. | D7: Fecha Cargo | E7: Descripción | F7: Cargo ($) | G7: Abono ($) | H7: Categoría | I7: Subcategoría | J7: Quincena | K7: Notas
B8: 1 | C8: 01/04/2026 | D8: 06/04/2026 | E8: COSTCO LOS CABOS | F8: 588 | H8: Alimentación | I8: Súper/Despensa | J8: 1ra Quincena Abr | K8: Tarjeta Titular
B9: 2 | C9: 01/04/2026 | D9: 06/04/2026 | E9: OXXO PEDROZA CEN | F9: 143 | H9: Alimentación | I9: Tienda/Conveniencia | J9: 1ra Quincena Abr | K9: Tarjeta Titular
B10: 3 | C10: 01/04/2026 | D10: 01/04/2026 | E10: SU ABONO...GRACIAS | G10: 4600 | H10: Abono | I10: Pago tarjeta | J10: 1ra Quincena Abr | K10: Tarjeta Titular
B11: 4 | C11: 01/04/2026 | D11: 06/04/2026 | E11: RAPPI VERIFICACION - ABONO | G11: 27.48 | H11: Alimentación | I11: Delivery | J11: 1ra Quincena Abr | K11: Tarjeta Digital
B12: 5 | C12: 02/04/2026 | D12: 06/04/2026 | E12: OXXOSAN BERNABE CEN | F12: 98 | H12: Alimentación | I12: Tienda/Conveniencia | J12: 1ra Quincena Abr | K12: Tarjeta Titular
B13: 6 | C13: 03/04/2026 | D13: 06/04/2026 | E13: OXXOSAN BERNABE CEN | F13: 332.5 | H13: Alimentación | I13: Tienda/Conveniencia | J13: 1ra Quincena Abr | K13: Tarjeta Titular
B14: 7 | C14: 04/04/2026 | D14: 06/04/2026 | E14: COSTCO LOS CABOS | F14: 129 | H14: Alimentación | I14: Súper/Despensa | J14: 1ra Quincena Abr | K14: Tarjeta Titular
B15: 8 | C15: 04/04/2026 | D15: 06/04/2026 | E15: OPENPAY*CAFFENIO RECARGA | F15: 100 | H15: Alimentación | I15: Café/Caffenio | J15: 1ra Quincena Abr | K15: Tarjeta Digital
B16: 9 | C16: 05/04/2026 | D16: 06/04/2026 | E16: OXXOSAN BERNABE CEN | F16: 217.5 | H16: Alimentación | I16: Tienda/Conveniencia | J16: 1ra Quincena Abr | K16: Tarjeta Titular
B17: 10 | C17: 06/04/2026 | D17: 07/04/2026 | E17: MERPAGO*DENTAL | F17: 900 | H17: Salud | I17: Dental | J17: 1ra Quincena Abr | K17: Tarjeta Titular
B18: 11 | C18: 06/04/2026 | D18: 07/04/2026 | E18: BURGER KING | F18: 411 | H18: Alimentación | I18: Restaurantes | J18: 1ra Quincena Abr | K18: Tarjeta Titular
B19: 12 | C19: 06/04/2026 | D19: 07/04/2026 | E19: GASO AEROPUERTO | F19: 200 | H19: Transporte | I19: Gasolina | J19: 1ra Quincena Abr | K19: Tarjeta Titular
B20: 13 | C20: 06/04/2026 | D20: 08/04/2026 | E20: COSTCO LOS CABOS - ABONO | G20: 129 | H20: Alimentación | I20: Súper/Despensa | J20: 1ra Quincena Abr | K20: Tarjeta Titular
B21: 14 | C21: 06/04/2026 | D21: 08/04/2026 | E21: COSTCO GAS LOS CABOS | F21: 776.51 | H21: Transporte | I21: Gasolina | J21: 1ra Quincena Abr | K21: Tarjeta Titular
B22: 15 | C22: 06/04/2026 | D22: 08/04/2026 | E22: COSTCO LOS CABOS | F22: 633.2 | H22: Alimentación | I22: Súper/Despensa | J22: 1ra Quincena Abr | K22: Tarjeta Titular
B23: 16 | C23: 06/04/2026 | D23: 08/04/2026 | E23: AMAZON | F23: 144.97 | H23: Compras Online | I23: Amazon | J23: 1ra Quincena Abr | K23: Tarjeta Titular
B24: 17 | C24: 06/04/2026 | D24: 07/04/2026 | E24: OPENPAY*CAFFENIO RECARGA | F24: 100 | H24: Alimentación | I24: Café/Caffenio | J24: 1ra Quincena Abr | K24: Tarjeta Digital
B25: 18 | C25: 07/04/2026 | D25: 08/04/2026 | E25: GB 3 FORJADORES | F25: 161 | H25: Deudas/Crédito | I25: GBM/Inversión | J25: 1ra Quincena Abr | K25: Tarjeta Titular
B26: 19 | C26: 07/04/2026 | D26: 09/04/2026 | E26: DIESGAS Q64 | F26: 700 | H26: Transporte | I26: Gasolina | J26: 1ra Quincena Abr | K26: Tarjeta Titular
B27: 20 | C27: 07/04/2026 | D27: 08/04/2026 | E27: OPENPAY*CAFFENIO RECARGA | F27: 100 | H27: Alimentación | I27: Café/Caffenio | J27: 1ra Quincena Abr | K27: Tarjeta Digital
B28: 21 | C28: 07/04/2026 | D28: 08/04/2026 | E28: STRIPE *WWW CHUYALMADA | F28: 347 | H28: Otros | I28: Pago online | J28: 1ra Quincena Abr | K28: Tarjeta Digital
B29: 22 | C29: 08/04/2026 | D29: 09/04/2026 | E29: NETFLIX COM | F29: 329 | H29: Entretenimiento | I29: Streaming | J29: 1ra Quincena Abr | K29: Tarjeta Digital
B30: 23 | C30: 08/04/2026 | D30: 09/04/2026 | E30: STRIPE *WWW SHEIN COM | F30: 855.35 | H30: Ropa/Personal | I30: Ropa SHEIN | J30: 1ra Quincena Abr | K30: Tarjeta Digital
B31: 24 | C31: 11/04/2026 | D31: 13/04/2026 | E31: MERPAGO*RICARDO | F31: 340 | H31: Salud | I31: Médico | J31: 1ra Quincena Abr | K31: Tarjeta Titular
B32: 25 | C32: 11/04/2026 | D32: 13/04/2026 | E32: SU ABONO...GRACIAS | G32: 555 | H32: Abono | I32: Pago tarjeta | J32: 1ra Quincena Abr | K32: Tarjeta Titular
B33: 26 | C33: 11/04/2026 | D33: 13/04/2026 | E33: SU ABONO...GRACIAS | G33: 415 | H33: Abono | I33: Pago tarjeta | J33: 1ra Quincena Abr | K33: Tarjeta Titular
B34: 27 | C34: 12/04/2026 | D34: 14/04/2026 | E34: OXXOSAN BERNABE CEN | F34: 98 | H34: Alimentación | I34: Tienda/Conveniencia | J34: 1ra Quincena Abr | K34: Tarjeta Titular
B35: 28 | C35: 14/04/2026 | D35: 15/04/2026 | E35: GASOL TRANSP 3 ESP | F35: 917.4 | H35: Transporte | I35: Gasolina | J35: 1ra Quincena Abr | K35: Tarjeta Titular
B36: 29 | C36: 14/04/2026 | D36: 15/04/2026 | E36: REST PEZGALLO LOS CABOS | F36: 212.75 | H36: Alimentación | I36: Restaurantes | J36: 1ra Quincena Abr | K36: Tarjeta Titular
B37: 30 | C37: 15/04/2026 | D37: 16/04/2026 | E37: OPENPAY*CAFFENIO RECARGA | F37: 50 | H37: Alimentación | I37: Café/Caffenio | J37: 1ra Quincena Abr | K37: Tarjeta Digital
B38: 31 | C38: 15/04/2026 | D38: 16/04/2026 | E38: OPENPAY*CAFFENIO RECARGA | F38: 50 | H38: Alimentación | I38: Café/Caffenio | J38: 1ra Quincena Abr | K38: Tarjeta Digital
B39: 32 | C39: 16/03/2026 | D39: 18/03/2026 | E39: COSTCO LOS CABOS | F39: 5 | H39: Alimentación | I39: Súper/Despensa | J39: 2da Quincena Mar | K39: Tarjeta Titular
B40: 33 | C40: 16/04/2026 | D40: 16/04/2026 | E40: SU ABONO...GRACIAS | G40: 5000 | H40: Abono | I40: Pago tarjeta | J40: 2da Quincena Abr | K40: Tarjeta Titular
B41: 34 | C41: 17/04/2026 | D41: 20/04/2026 | E41: CARLS JR SAN JOSE CABO | F41: 196 | H41: Alimentación | I41: Restaurantes | J41: 2da Quincena Abr | K41: Tarjeta Titular
B42: 35 | C42: 17/04/2026 | D42: 20/04/2026 | E42: OXXOSAN BERNABE CEN | F42: 98 | H42: Alimentación | I42: Tienda/Conveniencia | J42: 2da Quincena Abr | K42: Tarjeta Titular
B43: 36 | C43: 18/04/2026 | D43: 20/04/2026 | E43: MERPAGO*TACOSRANGER | F43: 300 | H43: Alimentación | I43: Restaurantes | J43: 2da Quincena Abr | K43: Tarjeta Titular
...

Sheet 🧾 Tickets-Productos
B2: 🧾 REGISTRO DE PRODUCTOS — Desglose de Tickets
B3: 📸 Manda la foto de tu ticket al chat → yo extraigo los productos y los agrego aquí automáticamente
B5: 🧾 Tickets registrados — | C5: 📦 Productos distintos — | D5: 💸 Gasto total productos — | E5: 🏆 Tienda más frecuente —
B7: Fecha | C7: Tienda | D7: Producto | E7: Cant. | F7: Precio Unit. | G7: Total ($) | H7: Categoría
B8: 12/12/2025 | C8: OXXO San Bernabé | D8: CHAMOY MEGA 500GR | E8: 1 | F8: 23 | G8: 23 | H8: 🍿 Botanas y Dulces
B9: 12/12/2025 | C9: OXXO San Bernabé | D9: DORITOS NACHO 61G | E9: 1 | F9: 19 | G9: 19 | H9: 🍿 Botanas y Dulces
B10: 12/12/2025 | C10: OXXO San Bernabé | D10: CHEETOS TORCIDIT 58G | E10: 1 | F10: 19 | G10: 19 | H10: 🍿 Botanas y Dulces
B11: 12/12/2025 | C11: OXXO San Bernabé | D11: SIDRAL MUNDET 600ML | E11: 1 | F11: 22 | G11: 22 | H11: 🥤 Bebidas
B12: 12/12/2025 | C12: OXXO San Bernabé | D12: TOPOCHICO LIMON 600ML | E12: 1 | F12: 25 | G12: 25 | H12: 🥤 Bebidas
B13: 12/12/2025 | C13: OXXO San Bernabé | D13: LUCKY STRIKE OR 100S | E13: 1 | F13: 82 | G13: 82 | H13: 🚬 Tabaco
B14: 12/12/2025 | C14: OXXO San Bernabé | D14: GILLETTE CUERPO 1PZ | E14: 1 | F14: 25 | G14: 25 | H14: 🧴 Belleza/Personal
B15: 15/12/2025 | C15: OXXO San Bernabé | D15: COCA-COLA NR 600ML | E15: 2 | F15: 18.5 | G15: 37 | H15: 🥤 Bebidas
B16: 21/12/2025 | C16: OXXO San Bernabé | D16: PACIFICO CLARA RT12L | E16: 2 | F16: 44 | G16: 88 | H16: 🥤 Bebidas
B17: 21/12/2025 | C17: OXXO San Bernabé | D17: COCA-COLA 500ML | E17: 2 | F17: 15 | G17: 30 | H17: 🥤 Bebidas
B18: 21/12/2025 | C18: OXXO San Bernabé | D18: CHOCOLATE KINDER SOR | E18: 1 | F18: 36 | G18: 36 | H18: 🍿 Botanas y Dulces
B19: 21/12/2025 | C19: OXXO San Bernabé | D19: HUEVITO KINDER SORPR | E19: 1 | F19: 36 | G19: 36 | H19: 🍿 Botanas y Dulces
... B125: 31/05/2026 | C125: Asadero Betsaida | D125: SUPER COMBO | E125: 1 | F125: 400 | G125: 400 | H125: 🍔 Comida/Restaurante
B126: TOTAL REGISTRADO (118 productos reales — Dic 2025 a May 2026) | G126: =SUM(G8:G125) -> 16504.63

Sheet 📊 Análisis Tickets
B2: 📊 ANÁLISIS DE FRECUENCIA, PRECIOS Y TENDENCIAS
B4: 🏆 TOP PRODUCTOS MÁS COMPRADOS | I4: Categoría | J4: Gasto
B5: Producto | C5: Veces comprado | D5: Total gastado | E5: Precio promedio | F5: Última tienda | I5: Carnes y Proteínas | J5: 1867
B6: 🥇 POLLO ENTERO KIRKLAND | C6: 4 | D6: 774 | E6: 193 | F6: Costco | I6: Lácteos y Huevo | J6: 1145
B7: 🥈 CHOCOLATE CARLOS V | C7: 4 | D7: 48 | E7: 12 | F7: OXXO | I7: Abarrotes/Despensa | J7: 1026
B8: 🥉 HUEVO BLANCO 30PZ | C8: 3 | D8: 267 | E8: 89 | F8: Costco | I8: Limpieza Hogar | J8: 364.2
B9: AGUA EPURA 12PZ | C9: 3 | D9: 198 | E9: 66 | F9: Costco | I9: Frutas y Verduras | J9: 306
B10: SALSA VALENTINA 370ML | C10: 3 | D10: 66 | E10: 22 | F10: Soriana | I10: Higiene Personal | J10: 266
B11: REFRESCO COCA-COLA 2L | C11: 3 | D11: 87 | E11: 29 | F11: Soriana | I11: Pan y Cereales | J11: 248.9
B12: SABRITAS ORIGINAL 45G | C12: 3 | D12: 54 | E12: 18 | F12: OXXO | I12: Bebidas | J12: 236
B13: LECHE ENTERA KIRKLAND 6PZ | C13: 2 | D13: 296 | E13: 148 | F13: Costco | I13: Botanas y Dulces | J13: 90
B14: PAN INTEGRAL BIMBO | C14: 2 | D14: 90 | E14: 45 | F14: Costco | I14: Otros | J14: 72
B15: ACEITE KIRKLAND 3L | C15: 2 | D15: 378 | E15: 189 | F15: Costco
B16: PAPEL HIGIENICO 30R | C16: 2 | D16: 175.2 | E16: 87.6 | F16: Costco
B17: YOGURT KIRKLAND 12PZ | C17: 2 | D17: 196 | E17: 98 | F17: Costco
B18: DETERGENTE KIRKLAND 8KG | C18: 2 | D18: 412 | E18: 206 | F18: Costco
B19: QUESO MANCHEGO KG | C19: 2 | D19: 296 | E19: 148 | F19: Costco
B20: CREMA LALA 1KG | C20: 2 | D20: 90 | E20: 45 | F20: Costco
B21: SHAMPOO KIRKLAND 1L | C21: 2 | D21: 196 | E21: 98 | F21: Costco
B22: PLATANO TABASCO KG | C22: 2 | D22: 44 | E22: 22 | F22: Soriana
B23: JAMON DEL PACIFICO 200G | C23: 2 | D23: 90 | E23: 45 | F23: Soriana
B24: FRIJOL NEGRO 1KG | C24: 2 | D24: 64 | E24: 32 | F24: Soriana
B25: JABON ROMA 750G | C25: 2 | D25: 70 | E25: 35 | F25: Soriana
B28: 🗂️ GASTO POR CATEGORÍA DE PRODUCTO
B29: Categoría | C29: Artículos distintos | D29: Gasto total | E29: % del total | F29: Frecuencia
B30: 🥩 Carnes y Proteínas | C30: 8 | D30: 1867 | E30: 0.3321414 | F30: 16
B31: 🥛 Lácteos y Huevo | C31: 5 | D31: 1145 | E31: 0.20369679 | F31: 11
B32: 🥫 Abarrotes/Despensa | C32: 7 | D32: 1026 | E32: 0.18252655 | F32: 17
B33: 🧴 Limpieza Hogar | C33: 2 | D33: 364.2 | E33: 0.064791589 | F33: 3
B34: 🥦 Frutas y Verduras | C34: 7 | D34: 306 | E34: 0.054437744 | F34: 10
B35: 🧼 Higiene Personal | C35: 2 | D35: 266 | E35: 0.047321699 | F35: 4
B36: 🍞 Pan y Cereales | C36: 3 | D36: 248.9 | E36: 0.044279589 | F36: 4
B37: 🥤 Bebidas | C37: 2 | D37: 236 | E37: 0.041984665 | F37: 5
B38: 🍿 Botanas y Dulces | C38: 2 | D38: 90 | E38: 0.016011101 | F38: 5
B39: 📦 Otros | C39: 3 | D39: 72 | E39: 0.012808881 | F39: 4
B42: 🏪 COMPARATIVA POR TIENDA
B43: Tienda | C43: Visitas | D43: Gasto Total | E43: Ticket Promedio | F43: % del gasto
B44: Costco | C44: 3 | D44: 4548.1 | E44: 1516.0333 | F44: 0.8091121
B45: Soriana | C45: 1 | D45: 683 | E45: 683 | F45: 0.12150647
B46: OXXO | C46: 3 | D46: 390 | E46: 130 | F46: 0.069381438
...
